<?xml version="1.0" ?>
<!-- =================================================================================== -->
<!-- |    This document was autogenerated by xacro from smartcar.urdf.xacro            | -->
<!-- |    EDITING THIS FILE BY HAND IS NOT RECOMMENDED                                 | -->
<!-- =================================================================================== -->
<robot name="smartcar">
  <!-- ==================== Robot Base ==================== -->
  <!-- Base footprint and chassis -->
  <link name="base_link">
  </link>
  <link name="base_footprint">
    <inertial>
      <mass value="1"/>
      <inertia ixx="0.01" ixy="0.0" ixz="0.0" iyy="0.01" iyz="0.0" izz="0.02"/>
      <origin xyz="0 0 0"/>
    </inertial>
  </link>
  <joint name="base_footprint_joint" type="fixed">
    <parent link="base_link"/>
    <child link="base_footprint"/>
  </joint>
  <link name="chassis_link">
    <inertial>
      <mass value="3.0"/>
      <inertia ixx="0.007289000000000001" ixy="0.0" ixz="0.0" iyy="0.01657625" iyz="0.0" izz="0.02373725"/>
      <origin xyz="0 0 0"/>
    </inertial>
    <visual>
      <geometry>
        <box size="0.257 0.17 0.021333333333333333"/>
      </geometry>
    </visual>
  </link>
  <joint name="chassis_joint" type="fixed">
    <parent link="base_link"/>
    <child link="chassis_link"/>
    <origin xyz="0 0 0.04"/>
  </joint>
  <link name="front_left_wheel_link">
    <inertial>
      <mass value="0.5"/>
      <inertia ixx="0.00015404166666666667" ixy="0.0" ixz="0.0" iyy="0.00015404166666666667" iyz="0.0" izz="0.000256"/>
      <origin rpy="1.5707963267948966 0 0" xyz="0 0 0"/>
    </inertial>
    <visual>
      <origin rpy="1.5707963267948966 0 0" xyz="0 0 0"/>
      <geometry>
        <cylinder length="0.025" radius="0.032"/>
      </geometry>
    </visual>
    <collision>
      <origin rpy="1.5707963267948966 0 0" xyz="0 0 0"/>
      <geometry>
        <cylinder length="0.025" radius="0.032"/>
      </geometry>
    </collision>
  </link>
  <link name="front_left_wheel_steer_link">
    <visual>
      <geometry>
        <box size="0.01 0.01 0.01"/>
      </geometry>
      <origin rpy="0 0 0" xyz="0 0 0"/>
    </visual>
    <collision>
      <geometry>
        <box size="0.01 0.01 0.01"/>
      </geometry>
      <origin rpy="0 0 0" xyz="0 0 0"/>
    </collision>
    <inertial>
      <mass value="0.1"/>
      <origin rpy="0 0 0" xyz="0 0 0"/>
      <inertia ixx="1.6666666666666667e-06" ixy="0.0" ixz="0.0" iyy="1.6666666666666667e-06" iyz="0.0" izz="1.6666666666666667e-06"/>
    </inertial>
  </link>
  <joint name="front_left_wheel_steer_joint" type="revolute">
    <origin rpy="0 0 0" xyz="0.1285 0.11000000000000001 0.032"/>
    <parent link="base_link"/>
    <child link="front_left_wheel_steer_link"/>
    <axis xyz="0 0 1"/>
    <limit effort="10" lower="-0.7853981633974483" upper="0.7853981633974483" velocity="1"/>
  </joint>
  <joint name="front_left_wheel_joint" type="continuous">
    <origin rpy="0 0 0" xyz="0 0 0"/>
    <parent link="front_left_wheel_steer_link"/>
    <child link="front_left_wheel_link"/>
    <axis xyz="0 1 0"/>
  </joint>
  <link name="front_right_wheel_link">
    <inertial>
      <mass value="0.5"/>
      <inertia ixx="0.00015404166666666667" ixy="0.0" ixz="0.0" iyy="0.00015404166666666667" iyz="0.0" izz="0.000256"/>
      <origin rpy="1.5707963267948966 0 0" xyz="0 0 0"/>
    </inertial>
    <visual>
      <origin rpy="1.5707963267948966 0 0" xyz="0 0 0"/>
      <geometry>
        <cylinder length="0.025" radius="0.032"/>
      </geometry>
    </visual>
    <collision>
      <origin rpy="1.5707963267948966 0 0" xyz="0 0 0"/>
      <geometry>
        <cylinder length="0.025" radius="0.032"/>
      </geometry>
    </collision>
  </link>
  <link name="front_right_wheel_steer_link">
    <visual>
      <geometry>
        <box size="0.01 0.01 0.01"/>
      </geometry>
      <origin rpy="0 0 0" xyz="0 0 0"/>
    </visual>
    <collision>
      <geometry>
        <box size="0.01 0.01 0.01"/>
      </geometry>
      <origin rpy="0 0 0" xyz="0 0 0"/>
    </collision>
    <inertial>
      <mass value="0.1"/>
      <origin rpy="0 0 0" xyz="0 0 0"/>
      <inertia ixx="1.6666666666666667e-06" ixy="0.0" ixz="0.0" iyy="1.6666666666666667e-06" iyz="0.0" izz="1.6666666666666667e-06"/>
    </inertial>
  </link>
  <joint name="front_right_wheel_steer_joint" type="revolute">
    <origin rpy="0 0 0" xyz="0.1285 -0.11000000000000001 0.032"/>
    <parent link="base_link"/>
    <child link="front_right_wheel_steer_link"/>
    <axis xyz="0 0 1"/>
    <limit effort="10" lower="-0.7853981633974483" upper="0.7853981633974483" velocity="1"/>
  </joint>
  <joint name="front_right_wheel_joint" type="continuous">
    <origin rpy="0 0 0" xyz="0 0 0"/>
    <parent link="front_right_wheel_steer_link"/>
    <child link="front_right_wheel_link"/>
    <axis xyz="0 1 0"/>
  </joint>
  <link name="back_left_wheel_link">
    <inertial>
      <mass value="0.5"/>
      <inertia ixx="0.0001" ixy="0.0" ixz="0.0" iyy="0.0001" iyz="0.0" izz="0.0002"/>
      <origin rpy="1.5707963267948966 0 0" xyz="0 0 0"/>
    </inertial>
    <visual>
      <origin rpy="1.5707963267948966 0 0" xyz="0 0 0"/>
      <geometry>
        <cylinder length="0.025" radius="0.032"/>
      </geometry>
    </visual>
    <collision>
      <origin rpy="1.5707963267948966 0 0" xyz="0 0 0"/>
      <geometry>
        <cylinder length="0.025" radius="0.032"/>
      </geometry>
    </collision>
  </link>
  <joint name="back_left_wheel_joint" type="continuous">
    <parent link="base_link"/>
    <child link="back_left_wheel_link"/>
    <origin rpy="0 0 0" xyz="-0.1285 0.11000000000000001 0.032"/>
    <axis xyz="0 1 0"/>
  </joint>
  <link name="back_right_wheel_link">
    <inertial>
      <mass value="0.5"/>
      <inertia ixx="0.0001" ixy="0.0" ixz="0.0" iyy="0.0001" iyz="0.0" izz="0.0002"/>
      <origin rpy="1.5707963267948966 0 0" xyz="0 0 0"/>
    </inertial>
    <visual>
      <origin rpy="1.5707963267948966 0 0" xyz="0 0 0"/>
      <geometry>
        <cylinder length="0.025" radius="0.032"/>
      </geometry>
    </visual>
    <collision>
      <origin rpy="1.5707963267948966 0 0" xyz="0 0 0"/>
      <geometry>
        <cylinder length="0.025" radius="0.032"/>
      </geometry>
    </collision>
  </link>
  <joint name="back_right_wheel_joint" type="continuous">
    <parent link="base_link"/>
    <child link="back_right_wheel_link"/>
    <origin rpy="0 0 0" xyz="-0.1285 -0.11000000000000001 0.032"/>
    <axis xyz="0 1 0"/>
  </joint>
  <!-- ==================== Sensors ==================== -->
  <!-- IMU Sensor -->
  <link name="imu_link">
    <visual>
      <geometry>
        <box size="0.05 0.05 0.05"/>
      </geometry>
    </visual>
    <collision>
      <origin rpy="0 0 0" xyz="0 0 0"/>
      <geometry>
        <box size="0.1 0.1 0.1"/>
      </geometry>
    </collision>
    <inertial>
      <mass value="0.05"/>
      <inertia ixx="2.0833333333333336e-05" ixy="0.0" ixz="0.0" iyy="2.0833333333333336e-05" iyz="0.0" izz="2.0833333333333336e-05"/>
      <origin xyz="0 0 0"/>
    </inertial>
  </link>
  <joint name="imu_joint" type="fixed">
    <parent link="base_link"/>
    <child link="imu_link"/>
    <origin xyz="0 0 0.082"/>
  </joint>
  <gazebo reference="imu_link">
    <sensor name="imu_sensor" type="imu">
      <always_on>true</always_on>
      <update_rate>30.0</update_rate>
      <plugin filename="libgazebo_ros_imu_sensor.so" name="gazebo_ros_imu">
        <ros>
          <remapping>~/out:=/imu_data</remapping>
        </ros>
      </plugin>
    </sensor>
  </gazebo>
  <!-- Lidar Sensor -->
  <link name="sllidar_base_link">
    <visual>
      <geometry>
        <cylinder length="0.05" radius="0.03"/>
      </geometry>
    </visual>
    <collision>
      <origin rpy="0 0 0" xyz="0 0 0"/>
      <geometry>
        <cylinder length="0.05" radius="0.03"/>
      </geometry>
    </collision>
    <inertial>
      <mass value="0.05"/>
      <inertia ixx="2.1666666666666667e-05" ixy="0.0" ixz="0.0" iyy="2.1666666666666667e-05" iyz="0.0" izz="2.25e-05"/>
      <origin xyz="0 0 0"/>
    </inertial>
  </link>
  <joint name="lidar_joint" type="fixed">
    <parent link="base_link"/>
    <child link="sllidar_base_link"/>
    <origin xyz="0.0985 0 0.082"/>
  </joint>
  <gazebo reference="sllidar_base_link">
    <sensor name="lidar" type="ray">
      <pose> 0 0 0 0 0 0 </pose>
      <visualize>true</visualize>
      <update_rate>10</update_rate>
      <ray>
        <scan>
          <horizontal>
            <samples>360</samples>
            <min_angle>-3.141592653589793</min_angle>
            <max_angle>3.141592653589793</max_angle>
          </horizontal>
        </scan>
        <range>
          <min>0.3</min>
          <max>12</max>
        </range>
      </ray>
      <plugin filename="libgazebo_ros_ray_sensor.so" name="lidar_plugin">
        <ros>
          <argument>~/out:=scan</argument>
        </ros>
        <output_type>sensor_msgs/LaserScan</output_type>
        <frame_name>sllidar_base_link</frame_name>
      </plugin>
    </sensor>
  </gazebo>
  <!-- ==================== Gazebo Plugins ==================== -->
  <gazebo>
    <plugin filename="libcar_gazebo_plugin.so" name="car_gazebo_plugin"/>
  </gazebo>
</robot>
